<?xml version="1.0"?>
<!-- This URDF was automatically created by SolidWorks to URDF Exporter! Originally created by Stephen Brawner (brawner@gmail.com) 
     Commit Version: 1.6.0-4-g7f85cfe  Build Version: 1.6.7995.38578
     For more information, please see http://wiki.ros.org/sw_urdf_exporter -->
<robot
  name="bot_car" xmlns:xacro="http://ros.org/wiki/xacro">
  # Add this before base link
    <link name="dummy_link"></link>

    # Add this after base link
    <joint name="dummy_joint" type="fixed">
        <origin rpy="0 0 0" xyz="0 0 0" />
        <parent link="dummy_link"/>
        <child link="base_link"/>
    </joint>
    <link
      name="base_link">
      <inertial>
        <origin
          xyz="0 -2.2204E-16 0.0025599"
          rpy="0 0 0" />
        <mass
          value="8.9305" />
        <inertia
          ixx="0.17655"
          ixy="2.3915E-16"
          ixz="1.4725E-17"
          iyy="0.58847"
          iyz="-7.9055E-17"
          izz="0.75707" />
      </inertial>
      <visual>
        <origin
          xyz="0 0 0"
          rpy="0 0 0" />
        <geometry>
          <mesh
            filename="package://bot_car/meshes/base_link.STL" />
        </geometry>
        <material
          name="">
          <color
            rgba="0.79216 0.81961 0.93333 1" />
        </material>
      </visual>
      <collision>
        <origin
          xyz="0 0 0"
          rpy="0 0 0" />
        <geometry>
          <mesh
            filename="package://bot_car/meshes/base_link.STL" />
        </geometry>
      </collision>
    </link>
    <link
      name="axel1_Link">
      <inertial>
        <origin
          xyz="0.02952 -7.5228E-05 0.10977"
          rpy="0 0 0" />
        <mass
          value="0.35112" />
        <inertia
          ixx="0.00094417"
          ixy="1.4331E-06"
          ixz="-0.00044245"
          iyy="0.0015065"
          iyz="1.1275E-06"
          izz="0.00063487" />
      </inertial>
      <visual>
        <origin
          xyz="0 0 0"
          rpy="0 0 0" />
        <geometry>
          <mesh
            filename="package://bot_car/meshes/axel1_Link.STL" />
        </geometry>
        <material
          name="">
          <color
            rgba="0.79216 0.81961 0.93333 1" />
        </material>
      </visual>
      <collision>
        <origin
          xyz="0 0 0"
          rpy="0 0 0" />
        <geometry>
          <mesh
            filename="package://bot_car/meshes/axel1_Link.STL" />
        </geometry>
      </collision>
    </link>
    <joint
      name="axel1_Joint"
      type="continuous">
      <origin
        xyz="-0.254 -0.14581 0"
        rpy="3.1416 0 -1.5708" />
      <parent
        link="base_link" />
      <child
        link="axel1_Link" />
      <axis
        xyz="0 0 1" />
      <limit
        lower="0"
        upper="0"
        effort="0"
        velocity="0" />
    </joint>
    <link
      name="wheel1_Link">
      <inertial>
        <origin
          xyz="0.014007 0.0017535 0.050269"
          rpy="0 0 0" />
        <mass
          value="3.2685" />
        <inertia
          ixx="0.010493"
          ixy="-0.00022424"
          ixz="3.115E-09"
          iyy="0.012393"
          iyz="-2.6758E-08"
          izz="0.015669" />
      </inertial>
      <visual>
        <origin
          xyz="0 0 0"
          rpy="0 0 0" />
        <geometry>
          <mesh
            filename="package://bot_car/meshes/wheel1_Link.STL" />
        </geometry>
        <material
          name="">
          <color
            rgba="0.50196 0.50196 0.50196 1" />
        </material>
      </visual>
      <collision>
        <origin
          xyz="0 0 0"
          rpy="0 0 0" />
        <geometry>
          <mesh
            filename="package://bot_car/meshes/wheel1_Link.STL" />
        </geometry>
      </collision>
    </link>
    <joint
      name="wheel1_Joint"
      type="continuous">
      <origin
        xyz="0.127 -0.0010668 0.1524"
        rpy="-1.5708 0 1.5682" />
      <parent
        link="axel1_Link" />
      <child
        link="wheel1_Link" />
      <axis
        xyz="0 0 1" />
      <limit
        lower="0"
        upper="0"
        effort="0"
        velocity="0" />
    </joint>
    <link
      name="axel2_Link">
      <inertial>
        <origin
          xyz="-0.0291531649114402 -0.00464108377325489 0.109770522945522"
          rpy="0 0 0" />
        <mass
          value="0.351116445713541" />
        <inertia
          ixx="0.000958064531908339"
          ixy="-8.73162668047775E-05"
          ixz="0.000436944551365717"
          iyy="0.00149264492179922"
          iyz="6.95600725792809E-05"
          izz="0.000634869701298319" />
      </inertial>
      <visual>
        <origin
          xyz="0 0 0"
          rpy="0 0 0" />
        <geometry>
          <mesh
            filename="package://bot_car/meshes/axel2_Link.STL" />
        </geometry>
        <material
          name="">
          <color
            rgba="0.792156862745098 0.819607843137255 0.933333333333333 1" />
        </material>
      </visual>
      <collision>
        <origin
          xyz="0 0 0"
          rpy="0 0 0" />
        <geometry>
          <mesh
            filename="package://bot_car/meshes/axel2_Link.STL" />
        </geometry>
      </collision>
    </link>
    <joint
      name="axel2_Joint"
      type="continuous">
      <origin
        xyz="-0.254 0.14581 0"
        rpy="-3.1416 0 -1.5708" />
      <parent
        link="base_link" />
      <child
        link="axel2_Link" />
      <axis
        xyz="0 0 1" />
      <limit
        lower="0"
        upper="0"
        effort="0"
        velocity="0" />
    </joint>
    <link
      name="wheel2_Link">
      <inertial>
        <origin
          xyz="0.0132961974963511 0.00148528277873694 0.050268710221559"
          rpy="0 0 0" />
        <mass
          value="3.26848849254688" />
        <inertia
          ixx="0.0104851129971514"
          ixy="-0.000185707204777589"
          ixz="2.57694474396428E-09"
          iyy="0.012401228265323"
          iyz="-2.68170786321244E-08"
          izz="0.0156685424424456" />
      </inertial>
      <visual>
        <origin
          xyz="0 0 0"
          rpy="0 0 0" />
        <geometry>
          <mesh
            filename="package://bot_car/meshes/wheel2_Link.STL" />
        </geometry>
        <material
          name="">
          <color
            rgba="0.501960784313725 0.501960784313725 0.501960784313725 1" />
        </material>
      </visual>
      <collision>
        <origin
          xyz="0 0 0"
          rpy="0 0 0" />
        <geometry>
          <mesh
            filename="package://bot_car/meshes/wheel2_Link.STL" />
        </geometry>
      </collision>
    </link>
    <joint
      name="wheel2_Joint"
      type="continuous">
      <origin
        xyz="-0.125420642056681 -0.0199665356556891 0.1524"
        rpy="-1.5707963267949 0 -1.41292454108719" />
      <parent
        link="axel2_Link" />
      <child
        link="wheel2_Link" />
      <axis
        xyz="0 0 1" />
      <limit
        lower="0"
        upper="0"
        effort="0"
        velocity="0" />
    </joint>
    <link
      name="axel3_Link">
      <inertial>
        <origin
          xyz="0.253324000419153 -0.175320715998941 -0.109770522945522"
          rpy="0 0 0" />
        <mass
          value="0.351116445713541" />
        <inertia
          ixx="0.00150625046620845"
          ixy="-1.28748737892474E-05"
          ixz="-1.01318101988307E-05"
          iyy="0.000944458987499111"
          iyz="-0.000442330748521417"
          izz="0.00063486970129832" />
      </inertial>
      <visual>
        <origin
          xyz="0 0 0"
          rpy="0 0 0" />
        <geometry>
          <mesh
            filename="package://bot_car/meshes/axel3_Link.STL" />
        </geometry>
        <material
          name="">
          <color
            rgba="0.792156862745098 0.819607843137255 0.933333333333333 1" />
        </material>
      </visual>
      <collision>
        <origin
          xyz="0 0 0"
          rpy="0 0 0" />
        <geometry>
          <mesh
            filename="package://bot_car/meshes/axel3_Link.STL" />
        </geometry>
      </collision>
    </link>
    <joint
      name="axel3_Joint"
      type="fixed">
      <origin
        xyz="0 0 0"
        rpy="0 0 0" />
      <parent
        link="base_link" />
      <child
        link="axel3_Link" />
      <axis
        xyz="0 0 0" />
    </joint>
    <link
      name="wheel3_Link">
      <inertial>
        <origin
          xyz="0.0133779745420139 -0.000157756019403044 0.0502687107907218"
          rpy="0 0 0" />
        <mass
          value="3.26848849254691" />
        <inertia
          ixx="0.0104687354240864"
          ixy="5.32691440691177E-05"
          ixz="-7.3555215907115E-10"
          iyy="0.0124176058723457"
          iyz="-2.69291569394582E-08"
          izz="0.0156685424761554" />
      </inertial>
      <visual>
        <origin
          xyz="0 0 0"
          rpy="0 0 0" />
        <geometry>
          <mesh
            filename="package://bot_car/meshes/wheel3_Link.STL" />
        </geometry>
        <material
          name="">
          <color
            rgba="0.501960784313725 0.501960784313725 0.501960784313725 1" />
        </material>
      </visual>
      <collision>
        <origin
          xyz="0 0 0"
          rpy="0 0 0" />
        <geometry>
          <mesh
            filename="package://bot_car/meshes/wheel3_Link.STL" />
        </geometry>
      </collision>
    </link>
    <joint
      name="wheel3_Joint"
      type="continuous">
      <origin
        xyz="0.25109 -0.27277 -0.1524"
        rpy="-1.5708 0 -0.022902" />
      <parent
        link="axel3_Link" />
      <child
        link="wheel3_Link" />
      <axis
        xyz="0 0 1" />
      <limit
        lower="0"
        upper="0"
        effort="0"
        velocity="0" />
    </joint>
    <link
      name="axel4_Link">
      <inertial>
        <origin
          xyz="0.253163090663729 0.175316591330923 -0.109770522945525"
          rpy="0 0 0" />
        <mass
          value="0.351116445713541" />
        <inertia
          ixx="0.00150609336294752"
          ixy="1.59372822940795E-05"
          ixz="-1.25435085892834E-05"
          iyy="0.000944616090760031"
          iyz="0.000442268928433477"
          izz="0.000634869701298327" />
      </inertial>
      <visual>
        <origin
          xyz="0 0 0"
          rpy="0 0 0" />
        <geometry>
          <mesh
            filename="package://bot_car/meshes/axel4_Link.STL" />
        </geometry>
        <material
          name="">
          <color
            rgba="0.792156862745098 0.819607843137255 0.933333333333333 1" />
        </material>
      </visual>
      <collision>
        <origin
          xyz="0 0 0"
          rpy="0 0 0" />
        <geometry>
          <mesh
            filename="package://bot_car/meshes/axel4_Link.STL" />
        </geometry>
      </collision>
    </link>
    <joint
      name="axel4_Joint"
      type="fixed">
      <origin
        xyz="0 0 0"
        rpy="0 0 0" />
      <parent
        link="base_link" />
      <child
        link="axel4_Link" />
      <axis
        xyz="0 0 0" />
    </joint>
    <link
      name="wheel4_Link">
      <inertial>
        <origin
          xyz="0.00199883694253689 -0.013228734221754 -0.0502687131342379"
          rpy="0 0 0" />
        <mass
          value="3.2684884925469" />
        <inertia
          ixx="0.0123661017868047"
          ixy="0.000317111301516424"
          ixz="-2.65688094473E-08"
          iyy="0.0105202395254445"
          iyz="-4.45113290820402E-09"
          izz="0.0156685424970015" />
      </inertial>
      <visual>
        <origin
          xyz="0 0 0"
          rpy="0 0 0" />
        <geometry>
          <mesh
            filename="package://bot_car/meshes/wheel4_Link.STL" />
        </geometry>
        <material
          name="">
          <color
            rgba="0.501960784313725 0.501960784313725 0.501960784313725 1" />
        </material>
      </visual>
      <collision>
        <origin
          xyz="0 0 0"
          rpy="0 0 0" />
        <geometry>
          <mesh
            filename="package://bot_car/meshes/wheel4_Link.STL" />
        </geometry>
      </collision>
    </link>
    <joint
      name="wheel4_Joint"
      type="continuous">
      <origin
        xyz="0.2504 0.27276 -0.1524"
        rpy="1.5708 0 -3.1132" />
      <parent
        link="axel4_Link" />
      <child
        link="wheel4_Link" />
      <axis
        xyz="0 0 -1" />
      <limit
        lower="0"
        upper="0"
        effort="0"
        velocity="0" />
    </joint>
#Lidar_Link and lidar_Joint added 
    <joint name="laser_joint" type="fixed">
        <parent link="base_link"/>
        <child link="laser_frame"/>
        <origin xyz="0 0 0.07" rpy="0 0 0"/>
    </joint>
 
    <link name="laser_frame">
        <visual>
            <geometry>
                <cylinder radius="0.05" length="0.04"/>
            </geometry>
            <material name="red"/>
        </visual>
        <collision>
            <geometry>
                <cylinder radius="0.05" length="0.04"/>
            </geometry>
        </collision>
        <!-- <xacro:inertial_cylinder mass="0.1" length="0.04" radius="0.05">
            <origin xyz="0 0 0" rpy="0 0 0"/>
        </xacro:inertial_cylinder> -->
    </link>

    <gazebo reference="laser_frame">
      <sensor name="lidar" type="ray">
        <pose>0.0 0.0 0.0 0 0 0</pose>
        <always_on>true</always_on>
        <visualize>true</visualize>
        <update_rate>5</update_rate>
        <ray>
          <scan>
            <horizontal>
              <samples>360</samples>
              <resolution>1.00000</resolution>
              <min_angle>0.000000</min_angle>
              <max_angle>6.280000</max_angle>
            </horizontal>
          </scan>
          <range>
            <min>0.120000</min>
            <max>3.5</max>
            <resolution>0.015000</resolution>
          </range>
          <noise>
            <type>gaussian</type>
            <mean>0.0</mean>
            <stddev>0.01</stddev>
          </noise>
        </ray>
        <plugin name="scan" filename="libgazebo_ros_ray_sensor.so">
          <ros>
            <remapping>~/out:=scan</remapping>
          </ros>
          <output_type>sensor_msgs/LaserScan</output_type>
          <frame_name>laser_frame</frame_name>
        </plugin>
      </sensor>
      </gazebo>

      <gazebo reference="base_link">
        <gravity>true</gravity>
        <sensor name="imu_sensor" type="imu">
          <always_on>true</always_on>
          <update_rate>100</update_rate>
          <visualize>true</visualize>
          <topic>__default_topic__</topic>
          <plugin filename="libgazebo_ros_imu_sensor.so" name="imu_plugin">
            <topicName>imu</topicName>
            <bodyName>base_link</bodyName>
            <updateRateHZ>10.0</updateRateHZ>
            <gaussianNoise>0.0</gaussianNoise>
            <xyzOffset>0 0 0</xyzOffset>
            <rpyOffset>0 0 0</rpyOffset>
            <frameName>base_link</frameName>
            <initialOrientationAsReference>false</initialOrientationAsReference>
          </plugin>
          <pose>0 0 0 0 0 0</pose>
        </sensor>
      </gazebo>

#ros2_controol framework is being added 

  <ros2_control name="GazeboSystem" type="system">
  <hardware>
    <plugin>gazebo_ros2_control/GazeboSystem</plugin>
  </hardware>
  <!-- Velocity Controllers for the Wheels -->
  <joint name="wheel1_Joint">
    <command_interface name="velocity">
      <param name="min">-1000.0</param>
      <param name="max">1000.0</param>
    </command_interface>
    <state_interface name="position"/>
    <state_interface name="velocity"/>
  </joint>
  <joint name="wheel2_Joint">
    <command_interface name="velocity">
      <param name="min">-1000.0</param>
      <param name="max">1000.0</param>
    </command_interface>
    <state_interface name="position"/>
    <state_interface name="velocity"/>
  </joint>
  <joint name="wheel3_Joint">
    <command_interface name="velocity">
      <param name="min">-1000.0</param>
      <param name="max">1000.0</param>
    </command_interface>
    <state_interface name="position"/>
    <state_interface name="velocity"/>
  </joint>
  <joint name="wheel4_Joint">
    <command_interface name="velocity">
      <param name="min">-1000.0</param>
      <param name="max">1000.0</param>
    </command_interface>
    <state_interface name="position"/>
    <state_interface name="velocity"/>
  </joint>
  <!-- Position Controllers for the Axles -->
  <joint name="axel1_Joint">
    <command_interface name="position">
      <param name="min">-3.14</param>
      <param name="max">3.14</param>
    </command_interface>
    <state_interface name="position"/>
    <state_interface name="velocity"/>
  </joint>
  <joint name="axel2_Joint">
    <command_interface name="position">
      <param name="min">-3.14</param>
      <param name="max">3.14</param>
    </command_interface>
    <state_interface name="position"/>
    <state_interface name="velocity"/>
  </joint>
    <!-- Fixed Axles (axel3_Joint and axel4_Joint are not actuated) -->
  </ros2_control>
  <gazebo>
    <plugin filename="libgazebo_ros2_control.so" name="gazebo_ros2_control">
        <parameters>$(find bot_car)/config/control.yaml</parameters>
    </plugin>
  </gazebo>

</robot>